[{"name": "unittest.loader._FailedTest.test.test_usemodule", "status": "errored", "message": "Failed to import test module: test.test_usemodule\nTraceback (most recent call last):\n  File \"/Users/carlygordon/opt/anaconda3/lib/python3.9/unittest/loader.py\", line 436, in _find_test_path\n    module = self._get_module_from_name(name)\n  File \"/Users/carlygordon/opt/anaconda3/lib/python3.9/unittest/loader.py\", line 377, in _get_module_from_name\n    __import__(name)\n  File \"/Users/carlygordon/Desktop/DataAnalysis/mooc-data-analysis-with-python-2022/part01-e20_usemodule/test/test_usemodule.py\", line 13, in <module>\n    from src import usemodule\n  File \"/Users/carlygordon/Desktop/DataAnalysis/mooc-data-analysis-with-python-2022/part01-e20_usemodule/src/usemodule.py\", line 12\n    if __name__ == \"__main__\":\n    ^\nIndentationError: expected an indented block\n", "passed": false, "points": [], "backtrace": ["  File \"/Users/carlygordon/opt/anaconda3/lib/python3.9/unittest/case.py\", line 59, in testPartExecutor\n    yield\n", "  File \"/Users/carlygordon/opt/anaconda3/lib/python3.9/unittest/case.py\", line 592, in run\n    self._callTestMethod(testMethod)\n", "  File \"/Users/carlygordon/opt/anaconda3/lib/python3.9/unittest/case.py\", line 550, in _callTestMethod\n    method()\n", "  File \"/Users/carlygordon/opt/anaconda3/lib/python3.9/unittest/loader.py\", line 34, in testFailure\n    raise self._exception\n"]}]